Workbook

Sheet I_3314566
C2: Código Norma | D2: Horas | E2: Competencia | F2: HORAS | G2: REST | H2: 1º | I2: 2º | J2: 3º | K2: 4º | L2: 5º | M2: 6º | N2: 7º | O2: Trim Calif | P2: Resultados | Q2: Ciclo SW
B3: ÁREA TÉCNICA | C3: 220501092 | D3: 144 | E3: ESPECIFICACIÓN DE REQUISITOS DEL SOFTWARE | F3: 36 | G3: =F3-SUM(H3:N3) -> 0 | H3: 36 | I3: 0 | J3: 0 | K3: 0 | L3: 0 | M3: 0 | N3: 0 | O3: 1º Trim | P3: 01 CARACTERIZAR LOS PROCESOS DE LA ORGANIZACIÓN DE ACUERDO CON EL SOFTWARE A CONSTRUIR. | Q3: 0- REQUISITOS
F4: 36 | G4: =F4-SUM(H4:N4) -> 0 | H4: 36 | I4: 0 | J4: 0 | K4: 0 | L4: 0 | M4: 0 | N4: 0 | O4: 1º Trim | P4: 02 RECOLECTAR INFORMACIÓN DEL SOFTWARE A CONSTRUIR DE ACUERDO CON LAS NECESIDADES DEL CLIENTE.
F5: 36 | G5: =F5-SUM(H5:N5) -> 0 | H5: 36 | I5: 0 | J5: 0 | K5: 0 | L5: 0 | M5: 0 | N5: 0 | O5: 1º Trim | P5: 03 ESTABLECER LOS REQUISITOS DEL SOFTWARE DE ACUERDO CON LA INFORMACIÓN RECOLECTADA.
F6: 36 | G6: =F6-SUM(H6:N6) -> 0 | H6: 36 | I6: 0 | J6: 0 | K6: 0 | L6: 0 | M6: 0 | N6: 0 | O6: 1º Trim | P6: 04 VALIDAR EL INFORME DE REQUISITOS DE ACUERDO CON LAS NECESIDADES DEL CLIENTE.
C7: 220501093 | D7: 288 | E7: ANÁLISIS DE LA ESPECIFICACIÓN DE REQUISITOS DEL SOFTWARE | F7: 71 | G7: =F7-SUM(H7:N7) -> 0 | H7: 0 | I7: 71 | J7: 0 | K7: 0 | L7: 0 | M7: 0 | N7: 0 | O7: 2º Trim | P7: 01 PLANEAR ACTIVIDADES DE ANÁLISIS DE ACUERDO CON LA METODOLOGÍA SELECCIONADA. | Q7: 1- ANÁLISIS
F8: 70 | G8: =F8-SUM(H8:N8) -> 0 | H8: 0 | I8: 70 | J8: 0 | K8: 0 | L8: 0 | M8: 0 | N8: 0 | O8: 2º Trim | P8: 02 MODELAR LAS FUNCIONES DEL SOFTWARE DE ACUERDO CON EL INFORME DE REQUISITOS.
F9: 77 | G9: =F9-SUM(H9:N9) -> 0 | H9: 77 | I9: 0 | J9: 0 | K9: 0 | L9: 0 | M9: 0 | N9: 0 | O9: 1º Trim | P9: 03 DESARROLLAR PROCESOS LÓGICOS A TRAVÉS DE LA IMPLEMENTACIÓN DE ALGORITMOS.
F10: 70 | G10: =F10-SUM(H10:N10) -> 0 | H10: 0 | I10: 0 | J10: 70 | K10: 0 | L10: 0 | M10: 0 | N10: 0 | O10: 3º Trim | P10: 04 VERIFICAR LOS MODELOS REALIZADOS EN LA FASE DE ANÁLISIS DE ACUERDO CON LO ESTABLECIDO EN EL INFORME DE REQUISITOS.
C11: 220501095 | D11: 336 | E11: MODELADO DE LOS ARTEFACTOS DEL SOFTWARE | F11: 84 | G11: =F11-SUM(H11:N11) -> 0 | H11: 0 | I11: 0 | J11: 84 | K11: 0 | L11: 0 | M11: 0 | N11: 0 | O11: 3º Trim | P11: 01 ELABORAR LOS ARTEFACTOS DE DISEÑO DEL SOFTWARE SIGUIENDO LAS PRÁCTICAS DE LA METODOLOGÍA SELECCIONADA. | Q11: 2- DISEÑO
F12: 84 | G12: =F12-SUM(H12:N12) -> 0 | H12: 0 | I12: 0 | J12: 84 | K12: 0 | L12: 0 | M12: 0 | N12: 0 | O12: 3º Trim | P12: 02 ESTRUCTURAR EL MODELO DE DATOS DEL SOFTWARE DE ACUERDO CON LAS ESPECIFICACIONES DEL ANÁLISIS.
F13: 84 | G13: =F13-SUM(H13:N13) -> 0 | H13: 0 | I13: 0 | J13: 0 | K13: 84 | L13: 0 | M13: 0 | N13: 0 | O13: 4º Trim | P13: 03 DETERMINAR LAS CARACTERÍSTICAS TÉCNICAS DE LA INTERFAZ GRÁFICA DEL SOFTWARE ADOPTANDO ESTÁNDARES.
F14: 84 | G14: =F14-SUM(H14:N14) -> 0 | H14: 0 | I14: 0 | J14: 0 | K14: 0 | L14: 84 | M14: 0 | N14: 0 | O14: 5º Trim | P14: 04 VERIFICAR LOS ENTREGABLES DE LA FASE DE DISEÑO DEL SOFTWARE DE ACUERDO CON LO ESTABLECIDO EN EL INFORME DE ANÁLISIS.
C15: 220501094 | D15: 144 | E15: ELABORACIÓN DE LA PROPUESTA TÉCNICA DEL SOFTWARE | F15: 48 | G15: =F15-SUM(H15:N15) -> 0 | H15: 0 | I15: 0 | J15: 48 | K15: 0 | L15: 0 | M15: 0 | N15: 0 | O15: 3º Trim | P15: 01 DEFINIR ESPECIFICACIONES TÉCNICAS DEL SOFTWARE DE ACUERDO CON LAS CARACTERÍSTICAS DEL SOFTWARE A CONSTRUIR. | Q15: 2- DISEÑO
F16: 48 | G16: =F16-SUM(H16:N16) -> 0 | H16: 0 | I16: 0 | J16: 0 | K16: 48 | L16: 0 | M16: 0 | N16: 0 | O16: 4º Trim | P16: 02 ELABORAR PROPUESTA TÉCNICA DEL SOFTWARE DE ACUERDO CON LAS ESPECIFICACIONES TÉCNICAS DEFINIDAS.
F17: 48 | G17: =F17-SUM(H17:N17) -> 0 | H17: 0 | I17: 0 | J17: 0 | K17: 0 | L17: 48 | M17: 0 | N17: 0 | O17: 5º Trim | P17: 03 VALIDAR LAS CONDICIONES DE LA PROPUESTA TÉCNICA DEL SOFTWARE DE ACUERDO CON LOS INTERESES DE LAS PARTES.
C18: 220501096 | D18: =SUM(F18:F22) -> 1008 | E18: CONSTRUCCIÓN DEL SOFTWARE | F18: 140 | G18: =F18-SUM(H18:N18) -> 0 | H18: 77 | I18: 0 | J18: 0 | K18: 0 | L18: 0 | M18: 31 | N18: 32 | O18: 7º Trim | P18: 01 PLANEAR ACTIVIDADES DE CONSTRUCCIÓN DEL SOFTWARE DE ACUERDO CON EL DISEÑO ESTABLECIDO. | Q18: 3- IMPLEMENTACIÓN
F19: 150 | G19: =F19-SUM(H19:N19) -> 0 | H19: 0 | I19: 0 | J19: 0 | K19: 50 | L19: 30 | M19: 30 | N19: 40 | O19: 7º Trim | P19: 02 CONSTRUIR LA BASE DE DATOS PARA EL SOFTWARE A PARTIR DEL MODELO DE DATOS.
F20: 210 | G20: =F20-SUM(H20:N20) -> 0 | H20: 0 | I20: 70 | J20: 0 | K20: 0 | L20: 0 | M20: 45 | N20: 95 | O20: 7º Trim | P20: 03 CREAR COMPONENTES FRONT-END DEL SOFTWARE DE ACUERDO CON EL DISEÑO.
F21: 368 | G21: =F21-SUM(H21:N21) -> 0 | H21: 0 | I21: 77 | J21: 0 | K21: 56 | L21: 0 | M21: 92 | N21: 143 | O21: 7º Trim | P21: 04 CODIFICAR EL SOFTWARE DE ACUERDO CON EL DISEÑO ESTABLECIDO.
F22: 140 | G22: =F22-SUM(H22:N22) -> 0 | H22: 0 | I22: 0 | J22: 0 | K22: 0 | L22: 76 | M22: 64 | N22: 0 | O22: 6º Trim | P22: 05 REALIZAR PRUEBAS AL SOFTWARE PARA VERIFICAR SU FUNCIONALIDAD.
C23: 220501098 | D23: 144 | E23: ADOPCIÓN DE BUENAS PRÁCTICAS EN EL PROCESO DE DESARROLLO DE SOFTWARE | F23: 48 | G23: =F23-SUM(H23:N23) -> 0 | H23: 0 | I23: 0 | J23: 0 | K23: 48 | L23: 0 | M23: 0 | N23: 0 | O23: 4º Trim | P23: 01 INCORPORAR ACTIVIDADES DE ASEGURAMIENTO DE LA CALIDAD DEL SOFTWARE DE ACUERDO CON ESTÁNDARES DE LA INDUSTRIA. | Q23: 3- IMPLEMENTACIÓN
F24: 48 | G24: =F24-SUM(H24:N24) -> 0 | H24: 0 | I24: 0 | J24: 0 | K24: 0 | L24: 48 | M24: 0 | N24: 0 | O24: 5º Trim | P24: 02 VERIFICAR LA CALIDAD DEL SOFTWARE DE ACUERDO CON LAS PRÁCTICAS ASOCIADAS EN LOS PROCESOS DE DESARROLLO.
F25: 48 | G25: =F25-SUM(H25:N25) -> 0 | H25: 0 | I25: 0 | J25: 0 | K25: 0 | L25: 0 | M25: 48 | N25: 0 | O25: 6º Trim | P25: 03 REALIZAR ACTIVIDADES DE MEJORA DE LA CALIDAD DEL SOFTWARE A PARTIR DE LOS RESULTADOS DE LA VERIFICACIÓN.
C26: 220501097 | D26: 144 | E26: IMPLANTACIÓN DEL SOFTWARE | F26: 36 | G26: =F26-SUM(H26:N26) -> 0 | H26: 0 | I26: 0 | J26: 0 | K26: 0 | L26: 0 | M26: 0 | N26: 36 | O26: 7º Trim | P26: 01 PLANEAR ACTIVIDADES DE IMPLANTACIÓN DEL SOFTWARE DE ACUERDO CON LAS CONDICIONES DEL SISTEMA. | Q26: 4- PRUEBAS / DESPLIEGUE
F27: 36 | G27: =F27-SUM(H27:N27) -> 0 | H27: 0 | I27: 0 | J27: 0 | K27: 0 | L27: 0 | M27: 0 | N27: 36 | O27: 7º Trim | P27: 02 DESPLEGAR EL SOFTWARE DE ACUERDO CON LA ARQUITECTURA Y LAS POLÍTICAS ESTABLECIDAS.
F28: 36 | G28: =F28-SUM(H28:N28) -> 0 | H28: 0 | I28: 0 | J28: 0 | K28: 0 | L28: 0 | M28: 36 | N28: 0 | O28: 6º Trim | P28: 03 DOCUMENTAR EL PROCESO DE IMPLANTACIÓN DE SOFTWARE SIGUIENDO ESTÁNDARES DE CALIDAD.
F29: 36 | G29: =F29-SUM(H29:N29) -> 0 | H29: 0 | I29: 0 | J29: 0 | K29: 0 | L29: 0 | M29: 36 | N29: 0 | O29: 6º Trim | P29: 04 IMPLANTAR EL SOFTWARE DE ACUERDO CON LOS NIVELES DE SERVICIO ESTABLECIDOS CON EL CLIENTE.
E30: TOTALES ÁREA TÉCNICA: | F30: =SUM(F3:F29) -> 2208 | G30: =SUM(G3:G29) -> 0 | H30: =SUM(H3:H29) -> 298 | I30: =SUM(I3:I29) -> 288 | J30: =SUM(J3:J29) -> 286 | K30: =SUM(K3:K29) -> 286 | L30: =SUM(L3:L29) -> 286 | M30: =SUM(M3:M29) -> 382 | N30: =SUM(N3:N29) -> 382
B32: INGLÉS Y AREÁ TRANSVERSAL | C32: 240202501 | D32: 384 | E32: INGLÉS | F32: 48 | G32: =F32-SUM(H32:N32) -> 0 | H32: 48 | I32: 0 | J32: 0 | K32: 0 | L32: 0 | M32: 0 | N32: 0 | O32: 1º Trim | P32: 01 COMPRENDER INFORMACIÓN SOBRE SITUACIONES COTIDIANAS Y LABORALES ACTUALES Y FUTURAS A TRAVÉS DE INTERACCIONES SOCIALES DE FORMA ORAL Y ESCRITA.
F33: 48 | G33: =F33-SUM(H33:N33) -> 0 | H33: 0 | I33: 0 | J33: 48 | K33: 0 | L33: 0 | M33: 0 | N33: 0 | O33: 3º Trim | P33: 02 INTERCAMBIAR OPINIONES SOBRE SITUACIONES COTIDIANAS Y LABORALES ACTUALES, PASADAS Y FUTURAS EN CONTEXTOS SOCIALES ORALES Y ESCRITOS.
F34: 48 | G34: =F34-SUM(H34:N34) -> 0 | H34: 0 | I34: 0 | J34: 0 | K34: 0 | L34: 0 | M34: 0 | N34: 48 | O34: 7º Trim | P34: 03 DISCUTIR SOBRE POSIBLES SOLUCIONES A PROBLEMAS DENTRO DE UN RANGO VARIADO DE CONTEXTOS SOCIALES Y LABORALES.
F35: 48 | G35: =F35-SUM(H35:N35) -> 0 | H35: 0 | I35: 0 | J35: 0 | K35: 48 | L35: 0 | M35: 0 | N35: 0 | O35: 4º Trim | P35: 04 IMPLEMENTAR ACCIONES DE MEJORA RELACIONADAS CON EL USO DE EXPRESIONES, ESTRUCTURAS Y DESEMPEÑO SEGÚN LOS RESULTADOS DE APRENDIZAJE FORMULADOS PARA EL PROGRAMA.
F36: =48*2 -> 96 | G36: =F36-SUM(H36:N36) -> 0 | H36: 0 | I36: 0 | J36: 0 | K36: 0 | L36: 48 | M36: 48 | N36: 0 | O36: 6º Trim | P36: 05 PRESENTAR UN PROCESO PARA LA REALIZACIÓN DE UNA ACTIVIDAD EN SU QUEHACER LABORAL DE ACUERDO CON LOS PROCEDIMIENTOS ESTABLECIDOS DESDE SU PROGRAMA DE FORMACIÓN.
F37: 48 | G37: =F37-SUM(H37:N37) -> 0 | H37: 0 | I37: 48 | J37: 0 | K37: 0 | L37: 0 | M37: 0 | N37: 0 | O37: 2º Trim | P37: 06 EXPLICAR LAS FUNCIONES DE SU OCUPACIÓN LABORAL USANDO EXPRESIONES DE ACUERDO AL NIVEL REQUERIDO POR EL PROGRAMA DE FORMACIÓN.
C38: 240201530 | D38: 48 | E38: INDUCCIÓN | F38: 48 | G38: =F38-SUM(H38:N38) -> 0 | H38: 48 | I38: 0 | J38: 0 | K38: 0 | L38: 0 | M38: 0 | N38: 0 | O38: 1º Trim | P38: 01 IDENTIFICAR LA DINÁMICA ORGANIZACIONAL DEL SENA Y EL ROL DE LA FORMACIÓN PROFESIONAL INTEGRAL DE ACUERDO CON SU PROYECTO DE VIDA Y EL DESARROLLO PROFESIONAL.
C39: 220501046 | D39: 48 | E39: TIC | F39: =48/4 -> 12 | G39: =F39-SUM(H39:N39) -> 0 | H39: 12 | I39: 0 | J39: 0 | K39: 0 | L39: 0 | M39: 0 | N39: 0 | O39: 1º Trim | P39: 01 ALISTAR HERRAMIENTAS DE TECNOLOGÍAS DE LA INFORMACIÓN Y LA COMUNICACIÓN (TIC), DE ACUERDO CON LAS NECESIDADES DE PROCESAMIENTO DE INFORMACIÓN Y COMUNICACIÓN.
F40: =48/4 -> 12 | G40: =F40-SUM(H40:N40) -> 0 | H40: 12 | I40: 0 | J40: 0 | K40: 0 | L40: 0 | M40: 0 | N40: 0 | O40: 1º Trim | P40: 02 APLICAR FUNCIONALIDADES DE HERRAMIENTAS Y SERVICIOS TIC, DE ACUERDO CON MANUALES DE USO, PROCEDIMIENTOS ESTABLECIDOS Y BUENAS PRÁCTICAS.
F41: =48/4 -> 12 | G41: =F41-SUM(H41:N41) -> 0 | H41: 12 | I41: 0 | J41: 0 | K41: 0 | L41: 0 | M41: 0 | N41: 0 | O41: 1º Trim | P41: 03 EVALUAR LOS RESULTADOS, DE ACUERDO CON LOS REQUERIMIENTOS
F42: =48/4 -> 12 | G42: =F42-SUM(H42:N42) -> 0 | H42: 12 | I42: 0 | J42: 0 | K42: 0 | L42: 0 | M42: 0 | N42: 0 | O42: 1º Trim | P42: 04 OPTIMIZAR LOS RESULTADOS, DE ACUERDO CON LA VERIFICACIÓN.
...

Sheet II_3314566
C2: Código Norma | D2: Horas | E2: Competencia | F2: HORAS | G2: REST | H2: 1º | I2: 2º | J2: 3º | K2: 4º | L2: 5º | M2: 6º | N2: 7º | O2: Trim Calif | P2: Resultados | Q2: Ciclo SW
B3: ÁREA TÉCNICA | C3: 220501092 | D3: 144 | E3: ESPECIFICACIÓN DE REQUISITOS DEL SOFTWARE | F3: 36 | G3: =F3-SUM(H3:N3) -> 0 | H3: 36 | I3: 0 | J3: 0 | K3: 0 | L3: 0 | M3: 0 | N3: 0 | O3: 1º Trim | P3: 01 CARACTERIZAR LOS PROCESOS DE LA ORGANIZACIÓN DE ACUERDO CON EL SOFTWARE A CONSTRUIR. | Q3: 0- REQUISITOS
F4: 36 | G4: =F4-SUM(H4:N4) -> 0 | H4: 36 | I4: 0 | J4: 0 | K4: 0 | L4: 0 | M4: 0 | N4: 0 | O4: 1º Trim | P4: 02 RECOLECTAR INFORMACIÓN DEL SOFTWARE A CONSTRUIR DE ACUERDO CON LAS NECESIDADES DEL CLIENTE.
F5: 36 | G5: =F5-SUM(H5:N5) -> 0 | H5: 36 | I5: 0 | J5: 0 | K5: 0 | L5: 0 | M5: 0 | N5: 0 | O5: 1º Trim | P5: 03 ESTABLECER LOS REQUISITOS DEL SOFTWARE DE ACUERDO CON LA INFORMACIÓN RECOLECTADA.
F6: 36 | G6: =F6-SUM(H6:N6) -> 0 | H6: 36 | I6: 0 | J6: 0 | K6: 0 | L6: 0 | M6: 0 | N6: 0 | O6: 1º Trim | P6: 04 VALIDAR EL INFORME DE REQUISITOS DE ACUERDO CON LAS NECESIDADES DEL CLIENTE.
C7: 220501093 | D7: 288 | E7: ANÁLISIS DE LA ESPECIFICACIÓN DE REQUISITOS DEL SOFTWARE | F7: 71 | G7: =F7-SUM(H7:N7) -> 0 | H7: 0 | I7: 71 | J7: 0 | K7: 0 | L7: 0 | M7: 0 | N7: 0 | O7: 2º Trim | P7: 01 PLANEAR ACTIVIDADES DE ANÁLISIS DE ACUERDO CON LA METODOLOGÍA SELECCIONADA. | Q7: 1- ANÁLISIS
F8: 70 | G8: =F8-SUM(H8:N8) -> 0 | H8: 0 | I8: 70 | J8: 0 | K8: 0 | L8: 0 | M8: 0 | N8: 0 | O8: 2º Trim | P8: 02 MODELAR LAS FUNCIONES DEL SOFTWARE DE ACUERDO CON EL INFORME DE REQUISITOS.
F9: 77 | G9: =F9-SUM(H9:N9) -> 0 | H9: 77 | I9: 0 | J9: 0 | K9: 0 | L9: 0 | M9: 0 | N9: 0 | O9: 1º Trim | P9: 03 DESARROLLAR PROCESOS LÓGICOS A TRAVÉS DE LA IMPLEMENTACIÓN DE ALGORITMOS.
F10: 70 | G10: =F10-SUM(H10:N10) -> 0 | H10: 0 | I10: 0 | J10: 70 | K10: 0 | L10: 0 | M10: 0 | N10: 0 | O10: 3º Trim | P10: 04 VERIFICAR LOS MODELOS REALIZADOS EN LA FASE DE ANÁLISIS DE ACUERDO CON LO ESTABLECIDO EN EL INFORME DE REQUISITOS.
C11: 220501095 | D11: 336 | E11: MODELADO DE LOS ARTEFACTOS DEL SOFTWARE | F11: 84 | G11: =F11-SUM(H11:N11) -> 0 | H11: 0 | I11: 0 | J11: 84 | K11: 0 | L11: 0 | M11: 0 | N11: 0 | O11: 3º Trim | P11: 01 ELABORAR LOS ARTEFACTOS DE DISEÑO DEL SOFTWARE SIGUIENDO LAS PRÁCTICAS DE LA METODOLOGÍA SELECCIONADA. | Q11: 2- DISEÑO
F12: 84 | G12: =F12-SUM(H12:N12) -> 0 | H12: 0 | I12: 0 | J12: 84 | K12: 0 | L12: 0 | M12: 0 | N12: 0 | O12: 3º Trim | P12: 02 ESTRUCTURAR EL MODELO DE DATOS DEL SOFTWARE DE ACUERDO CON LAS ESPECIFICACIONES DEL ANÁLISIS.
F13: 84 | G13: =F13-SUM(H13:N13) -> 0 | H13: 0 | I13: 0 | J13: 0 | K13: 84 | L13: 0 | M13: 0 | N13: 0 | O13: 4º Trim | P13: 03 DETERMINAR LAS CARACTERÍSTICAS TÉCNICAS DE LA INTERFAZ GRÁFICA DEL SOFTWARE ADOPTANDO ESTÁNDARES.
F14: 84 | G14: =F14-SUM(H14:N14) -> 0 | H14: 0 | I14: 0 | J14: 0 | K14: 0 | L14: 84 | M14: 0 | N14: 0 | O14: 5º Trim | P14: 04 VERIFICAR LOS ENTREGABLES DE LA FASE DE DISEÑO DEL SOFTWARE DE ACUERDO CON LO ESTABLECIDO EN EL INFORME DE ANÁLISIS.
C15: 220501094 | D15: 144 | E15: ELABORACIÓN DE LA PROPUESTA TÉCNICA DEL SOFTWARE | F15: 48 | G15: =F15-SUM(H15:N15) -> 0 | H15: 0 | I15: 0 | J15: 48 | K15: 0 | L15: 0 | M15: 0 | N15: 0 | O15: 3º Trim | P15: 01 DEFINIR ESPECIFICACIONES TÉCNICAS DEL SOFTWARE DE ACUERDO CON LAS CARACTERÍSTICAS DEL SOFTWARE A CONSTRUIR. | Q15: 2- DISEÑO
F16: 48 | G16: =F16-SUM(H16:N16) -> 0 | H16: 0 | I16: 0 | J16: 0 | K16: 48 | L16: 0 | M16: 0 | N16: 0 | O16: 4º Trim | P16: 02 ELABORAR PROPUESTA TÉCNICA DEL SOFTWARE DE ACUERDO CON LAS ESPECIFICACIONES TÉCNICAS DEFINIDAS.
F17: 48 | G17: =F17-SUM(H17:N17) -> 0 | H17: 0 | I17: 0 | J17: 0 | K17: 0 | L17: 48 | M17: 0 | N17: 0 | O17: 5º Trim | P17: 03 VALIDAR LAS CONDICIONES DE LA PROPUESTA TÉCNICA DEL SOFTWARE DE ACUERDO CON LOS INTERESES DE LAS PARTES.
C18: 220501096 | D18: =SUM(F18:F22) -> 1008 | E18: CONSTRUCCIÓN DEL SOFTWARE | F18: 140 | G18: =F18-SUM(H18:N18) -> 0 | H18: 77 | I18: 0 | J18: 0 | K18: 0 | L18: 0 | M18: 31 | N18: 32 | O18: 7º Trim | P18: 01 PLANEAR ACTIVIDADES DE CONSTRUCCIÓN DEL SOFTWARE DE ACUERDO CON EL DISEÑO ESTABLECIDO. | Q18: 3- IMPLEMENTACIÓN
F19: 150 | G19: =F19-SUM(H19:N19) -> 0 | H19: 0 | I19: 0 | J19: 0 | K19: 50 | L19: 30 | M19: 30 | N19: 40 | O19: 7º Trim | P19: 02 CONSTRUIR LA BASE DE DATOS PARA EL SOFTWARE A PARTIR DEL MODELO DE DATOS.
F20: 210 | G20: =F20-SUM(H20:N20) -> 0 | H20: 0 | I20: 70 | J20: 0 | K20: 0 | L20: 0 | M20: 45 | N20: 95 | O20: 7º Trim | P20: 03 CREAR COMPONENTES FRONT-END DEL SOFTWARE DE ACUERDO CON EL DISEÑO.
F21: 368 | G21: =F21-SUM(H21:N21) -> 0 | H21: 0 | I21: 77 | J21: 0 | K21: 56 | L21: 0 | M21: 92 | N21: 143 | O21: 7º Trim | P21: 04 CODIFICAR EL SOFTWARE DE ACUERDO CON EL DISEÑO ESTABLECIDO.
F22: 140 | G22: =F22-SUM(H22:N22) -> 0 | H22: 0 | I22: 0 | J22: 0 | K22: 0 | L22: 76 | M22: 64 | N22: 0 | O22: 6º Trim | P22: 05 REALIZAR PRUEBAS AL SOFTWARE PARA VERIFICAR SU FUNCIONALIDAD.
C23: 220501098 | D23: 144 | E23: ADOPCIÓN DE BUENAS PRÁCTICAS EN EL PROCESO DE DESARROLLO DE SOFTWARE | F23: 48 | G23: =F23-SUM(H23:N23) -> 0 | H23: 0 | I23: 0 | J23: 0 | K23: 48 | L23: 0 | M23: 0 | N23: 0 | O23: 4º Trim | P23: 01 INCORPORAR ACTIVIDADES DE ASEGURAMIENTO DE LA CALIDAD DEL SOFTWARE DE ACUERDO CON ESTÁNDARES DE LA INDUSTRIA. | Q23: 3- IMPLEMENTACIÓN
F24: 48 | G24: =F24-SUM(H24:N24) -> 0 | H24: 0 | I24: 0 | J24: 0 | K24: 0 | L24: 48 | M24: 0 | N24: 0 | O24: 5º Trim | P24: 02 VERIFICAR LA CALIDAD DEL SOFTWARE DE ACUERDO CON LAS PRÁCTICAS ASOCIADAS EN LOS PROCESOS DE DESARROLLO.
F25: 48 | G25: =F25-SUM(H25:N25) -> 0 | H25: 0 | I25: 0 | J25: 0 | K25: 0 | L25: 0 | M25: 48 | N25: 0 | O25: 6º Trim | P25: 03 REALIZAR ACTIVIDADES DE MEJORA DE LA CALIDAD DEL SOFTWARE A PARTIR DE LOS RESULTADOS DE LA VERIFICACIÓN.
C26: 220501097 | D26: 144 | E26: IMPLANTACIÓN DEL SOFTWARE | F26: 36 | G26: =F26-SUM(H26:N26) -> 0 | H26: 0 | I26: 0 | J26: 0 | K26: 0 | L26: 0 | M26: 0 | N26: 36 | O26: 7º Trim | P26: 01 PLANEAR ACTIVIDADES DE IMPLANTACIÓN DEL SOFTWARE DE ACUERDO CON LAS CONDICIONES DEL SISTEMA. | Q26: 4- PRUEBAS / DESPLIEGUE
F27: 36 | G27: =F27-SUM(H27:N27) -> 0 | H27: 0 | I27: 0 | J27: 0 | K27: 0 | L27: 0 | M27: 0 | N27: 36 | O27: 7º Trim | P27: 02 DESPLEGAR EL SOFTWARE DE ACUERDO CON LA ARQUITECTURA Y LAS POLÍTICAS ESTABLECIDAS.
F28: 36 | G28: =F28-SUM(H28:N28) -> 0 | H28: 0 | I28: 0 | J28: 0 | K28: 0 | L28: 0 | M28: 36 | N28: 0 | O28: 6º Trim | P28: 03 DOCUMENTAR EL PROCESO DE IMPLANTACIÓN DE SOFTWARE SIGUIENDO ESTÁNDARES DE CALIDAD.
F29: 36 | G29: =F29-SUM(H29:N29) -> 0 | H29: 0 | I29: 0 | J29: 0 | K29: 0 | L29: 0 | M29: 36 | N29: 0 | O29: 6º Trim | P29: 04 IMPLANTAR EL SOFTWARE DE ACUERDO CON LOS NIVELES DE SERVICIO ESTABLECIDOS CON EL CLIENTE.
E30: TOTALES ÁREA TÉCNICA: | F30: =SUM(F3:F29) -> 2208 | G30: =SUM(G3:G29) -> 0 | H30: =SUM(H3:H29) -> 298 | I30: =SUM(I3:I29) -> 288 | J30: =SUM(J3:J29) -> 286 | K30: =SUM(K3:K29) -> 286 | L30: =SUM(L3:L29) -> 286 | M30: =SUM(M3:M29) -> 382 | N30: =SUM(N3:N29) -> 382
B32: INGLÉS Y AREÁ TRANSVERSAL | C32: 240202501 | D32: 384 | E32: INGLÉS | F32: 48 | G32: =F32-SUM(H32:N32) -> 0 | H32: 48 | I32: 0 | J32: 0 | K32: 0 | L32: 0 | M32: 0 | N32: 0 | O32: 1º Trim | P32: 01 COMPRENDER INFORMACIÓN SOBRE SITUACIONES COTIDIANAS Y LABORALES ACTUALES Y FUTURAS A TRAVÉS DE INTERACCIONES SOCIALES DE FORMA ORAL Y ESCRITA.
F33: 48 | G33: =F33-SUM(H33:N33) -> 0 | H33: 0 | I33: 0 | J33: 48 | K33: 0 | L33: 0 | M33: 0 | N33: 0 | O33: 3º Trim | P33: 02 INTERCAMBIAR OPINIONES SOBRE SITUACIONES COTIDIANAS Y LABORALES ACTUALES, PASADAS Y FUTURAS EN CONTEXTOS SOCIALES ORALES Y ESCRITOS.
F34: 48 | G34: =F34-SUM(H34:N34) -> 0 | H34: 0 | I34: 0 | J34: 0 | K34: 0 | L34: 0 | M34: 0 | N34: 48 | O34: 7º Trim | P34: 03 DISCUTIR SOBRE POSIBLES SOLUCIONES A PROBLEMAS DENTRO DE UN RANGO VARIADO DE CONTEXTOS SOCIALES Y LABORALES.
F35: 48 | G35: =F35-SUM(H35:N35) -> 0 | H35: 0 | I35: 0 | J35: 0 | K35: 48 | L35: 0 | M35: 0 | N35: 0 | O35: 4º Trim | P35: 04 IMPLEMENTAR ACCIONES DE MEJORA RELACIONADAS CON EL USO DE EXPRESIONES, ESTRUCTURAS Y DESEMPEÑO SEGÚN LOS RESULTADOS DE APRENDIZAJE FORMULADOS PARA EL PROGRAMA.
F36: =48*2 -> 96 | G36: =F36-SUM(H36:N36) -> 0 | H36: 0 | I36: 0 | J36: 0 | K36: 0 | L36: 48 | M36: 48 | N36: 0 | O36: 6º Trim | P36: 05 PRESENTAR UN PROCESO PARA LA REALIZACIÓN DE UNA ACTIVIDAD EN SU QUEHACER LABORAL DE ACUERDO CON LOS PROCEDIMIENTOS ESTABLECIDOS DESDE SU PROGRAMA DE FORMACIÓN.
F37: 48 | G37: =F37-SUM(H37:N37) -> 0 | H37: 0 | I37: 48 | J37: 0 | K37: 0 | L37: 0 | M37: 0 | N37: 0 | O37: 2º Trim | P37: 06 EXPLICAR LAS FUNCIONES DE SU OCUPACIÓN LABORAL USANDO EXPRESIONES DE ACUERDO AL NIVEL REQUERIDO POR EL PROGRAMA DE FORMACIÓN.
C38: 240201530 | D38: 48 | E38: INDUCCIÓN | F38: 48 | G38: =F38-SUM(H38:N38) -> 0 | H38: 48 | I38: 0 | J38: 0 | K38: 0 | L38: 0 | M38: 0 | N38: 0 | O38: 1º Trim | P38: 01 IDENTIFICAR LA DINÁMICA ORGANIZACIONAL DEL SENA Y EL ROL DE LA FORMACIÓN PROFESIONAL INTEGRAL DE ACUERDO CON SU PROYECTO DE VIDA Y EL DESARROLLO PROFESIONAL.
C39: 220501046 | D39: 48 | E39: TIC | F39: =48/4 -> 12 | G39: =F39-SUM(H39:N39) -> 0 | H39: 12 | I39: 0 | J39: 0 | K39: 0 | L39: 0 | M39: 0 | N39: 0 | O39: 1º Trim | P39: 01 ALISTAR HERRAMIENTAS DE TECNOLOGÍAS DE LA INFORMACIÓN Y LA COMUNICACIÓN (TIC), DE ACUERDO CON LAS NECESIDADES DE PROCESAMIENTO DE INFORMACIÓN Y COMUNICACIÓN.
F40: =48/4 -> 12 | G40: =F40-SUM(H40:N40) -> 0 | H40: 12 | I40: 0 | J40: 0 | K40: 0 | L40: 0 | M40: 0 | N40: 0 | O40: 1º Trim | P40: 02 APLICAR FUNCIONALIDADES DE HERRAMIENTAS Y SERVICIOS TIC, DE ACUERDO CON MANUALES DE USO, PROCEDIMIENTOS ESTABLECIDOS Y BUENAS PRÁCTICAS.
F41: =48/4 -> 12 | G41: =F41-SUM(H41:N41) -> 0 | H41: 12 | I41: 0 | J41: 0 | K41: 0 | L41: 0 | M41: 0 | N41: 0 | O41: 1º Trim | P41: 03 EVALUAR LOS RESULTADOS, DE ACUERDO CON LOS REQUERIMIENTOS
F42: =48/4 -> 12 | G42: =F42-SUM(H42:N42) -> 0 | H42: 12 | I42: 0 | J42: 0 | K42: 0 | L42: 0 | M42: 0 | N42: 0 | O42: 1º Trim | P42: 04 OPTIMIZAR LOS RESULTADOS, DE ACUERDO CON LA VERIFICACIÓN.
...

Sheet Competencias
C2: Código Norma | D2: Horas | E2: Competencia | F2: HORAS | G2: REST | H2: 1º | I2: 2º | J2: 3º | K2: 4º | L2: 5º | M2: 6º | N2: 7º | O2: Trim Calif | P2: Resultados | Q2: Ciclo SW
B3: ÁREA TÉCNICA | C3: 220501092 | D3: 144 | E3: ESPECIFICACIÓN DE REQUISITOS DEL SOFTWARE | F3: 36 | G3: =F3-SUM(H3:N3) -> 0 | H3: 36 | I3: 0 | J3: 0 | K3: 0 | L3: 0 | M3: 0 | N3: 0 | O3: 1º Trim | P3: 01 CARACTERIZAR LOS PROCESOS DE LA ORGANIZACIÓN DE ACUERDO CON EL SOFTWARE A CONSTRUIR. | Q3: 0- REQUISITOS
F4: 36 | G4: =F4-SUM(H4:N4) -> 0 | H4: 36 | I4: 0 | J4: 0 | K4: 0 | L4: 0 | M4: 0 | N4: 0 | O4: 1º Trim | P4: 02 RECOLECTAR INFORMACIÓN DEL SOFTWARE A CONSTRUIR DE ACUERDO CON LAS NECESIDADES DEL CLIENTE.
F5: 36 | G5: =F5-SUM(H5:N5) -> 0 | H5: 36 | I5: 0 | J5: 0 | K5: 0 | L5: 0 | M5: 0 | N5: 0 | O5: 1º Trim | P5: 03 ESTABLECER LOS REQUISITOS DEL SOFTWARE DE ACUERDO CON LA INFORMACIÓN RECOLECTADA.
F6: 36 | G6: =F6-SUM(H6:N6) -> 0 | H6: 36 | I6: 0 | J6: 0 | K6: 0 | L6: 0 | M6: 0 | N6: 0 | O6: 1º Trim | P6: 04 VALIDAR EL INFORME DE REQUISITOS DE ACUERDO CON LAS NECESIDADES DEL CLIENTE.
C7: 220501093 | D7: 288 | E7: ANÁLISIS DE LA ESPECIFICACIÓN DE REQUISITOS DEL SOFTWARE | F7: 71 | G7: =F7-SUM(H7:N7) -> 0 | H7: 0 | I7: 71 | J7: 0 | K7: 0 | L7: 0 | M7: 0 | N7: 0 | O7: 2º Trim | P7: 01 PLANEAR ACTIVIDADES DE ANÁLISIS DE ACUERDO CON LA METODOLOGÍA SELECCIONADA. | Q7: 1- ANÁLISIS
F8: 70 | G8: =F8-SUM(H8:N8) -> 0 | H8: 0 | I8: 70 | J8: 0 | K8: 0 | L8: 0 | M8: 0 | N8: 0 | O8: 2º Trim | P8: 02 MODELAR LAS FUNCIONES DEL SOFTWARE DE ACUERDO CON EL INFORME DE REQUISITOS.
F9: 77 | G9: =F9-SUM(H9:N9) -> 0 | H9: 77 | I9: 0 | J9: 0 | K9: 0 | L9: 0 | M9: 0 | N9: 0 | O9: 1º Trim | P9: 03 DESARROLLAR PROCESOS LÓGICOS A TRAVÉS DE LA IMPLEMENTACIÓN DE ALGORITMOS.
F10: 70 | G10: =F10-SUM(H10:N10) -> 0 | H10: 0 | I10: 0 | J10: 70 | K10: 0 | L10: 0 | M10: 0 | N10: 0 | O10: 3º Trim | P10: 04 VERIFICAR LOS MODELOS REALIZADOS EN LA FASE DE ANÁLISIS DE ACUERDO CON LO ESTABLECIDO EN EL INFORME DE REQUISITOS.
C11: 220501095 | D11: 336 | E11: MODELADO DE LOS ARTEFACTOS DEL SOFTWARE | F11: 84 | G11: =F11-SUM(H11:N11) -> 0 | H11: 0 | I11: 0 | J11: 84 | K11: 0 | L11: 0 | M11: 0 | N11: 0 | O11: 3º Trim | P11: 01 ELABORAR LOS ARTEFACTOS DE DISEÑO DEL SOFTWARE SIGUIENDO LAS PRÁCTICAS DE LA METODOLOGÍA SELECCIONADA. | Q11: 2- DISEÑO
F12: 84 | G12: =F12-SUM(H12:N12) -> 0 | H12: 0 | I12: 0 | J12: 84 | K12: 0 | L12: 0 | M12: 0 | N12: 0 | O12: 3º Trim | P12: 02 ESTRUCTURAR EL MODELO DE DATOS DEL SOFTWARE DE ACUERDO CON LAS ESPECIFICACIONES DEL ANÁLISIS.
F13: 84 | G13: =F13-SUM(H13:N13) -> 0 | H13: 0 | I13: 0 | J13: 0 | K13: 84 | L13: 0 | M13: 0 | N13: 0 | O13: 4º Trim | P13: 03 DETERMINAR LAS CARACTERÍSTICAS TÉCNICAS DE LA INTERFAZ GRÁFICA DEL SOFTWARE ADOPTANDO ESTÁNDARES.
F14: 84 | G14: =F14-SUM(H14:N14) -> 0 | H14: 0 | I14: 0 | J14: 0 | K14: 0 | L14: 84 | M14: 0 | N14: 0 | O14: 5º Trim | P14: 04 VERIFICAR LOS ENTREGABLES DE LA FASE DE DISEÑO DEL SOFTWARE DE ACUERDO CON LO ESTABLECIDO EN EL INFORME DE ANÁLISIS.
C15: 220501094 | D15: 144 | E15: ELABORACIÓN DE LA PROPUESTA TÉCNICA DEL SOFTWARE | F15: 48 | G15: =F15-SUM(H15:N15) -> 0 | H15: 0 | I15: 0 | J15: 48 | K15: 0 | L15: 0 | M15: 0 | N15: 0 | O15: 3º Trim | P15: 01 DEFINIR ESPECIFICACIONES TÉCNICAS DEL SOFTWARE DE ACUERDO CON LAS CARACTERÍSTICAS DEL SOFTWARE A CONSTRUIR. | Q15: 2- DISEÑO
F16: 48 | G16: =F16-SUM(H16:N16) -> 0 | H16: 0 | I16: 0 | J16: 0 | K16: 48 | L16: 0 | M16: 0 | N16: 0 | O16: 4º Trim | P16: 02 ELABORAR PROPUESTA TÉCNICA DEL SOFTWARE DE ACUERDO CON LAS ESPECIFICACIONES TÉCNICAS DEFINIDAS.
F17: 48 | G17: =F17-SUM(H17:N17) -> 0 | H17: 0 | I17: 0 | J17: 0 | K17: 0 | L17: 48 | M17: 0 | N17: 0 | O17: 5º Trim | P17: 03 VALIDAR LAS CONDICIONES DE LA PROPUESTA TÉCNICA DEL SOFTWARE DE ACUERDO CON LOS INTERESES DE LAS PARTES.
C18: 220501096 | D18: =SUM(F18:F22) -> 1008 | E18: CONSTRUCCIÓN DEL SOFTWARE | F18: 140 | G18: =F18-SUM(H18:N18) -> 0 | H18: 77 | I18: 0 | J18: 0 | K18: 0 | L18: 0 | M18: 31 | N18: 32 | O18: 7º Trim | P18: 01 PLANEAR ACTIVIDADES DE CONSTRUCCIÓN DEL SOFTWARE DE ACUERDO CON EL DISEÑO ESTABLECIDO. | Q18: 3- IMPLEMENTACIÓN
F19: 150 | G19: =F19-SUM(H19:N19) -> 0 | H19: 0 | I19: 0 | J19: 0 | K19: 50 | L19: 30 | M19: 30 | N19: 40 | O19: 7º Trim | P19: 02 CONSTRUIR LA BASE DE DATOS PARA EL SOFTWARE A PARTIR DEL MODELO DE DATOS.
F20: 210 | G20: =F20-SUM(H20:N20) -> 0 | H20: 0 | I20: 70 | J20: 0 | K20: 0 | L20: 0 | M20: 45 | N20: 95 | O20: 7º Trim | P20: 03 CREAR COMPONENTES FRONT-END DEL SOFTWARE DE ACUERDO CON EL DISEÑO.
F21: 368 | G21: =F21-SUM(H21:N21) -> 0 | H21: 0 | I21: 77 | J21: 0 | K21: 56 | L21: 0 | M21: 92 | N21: 143 | O21: 7º Trim | P21: 04 CODIFICAR EL SOFTWARE DE ACUERDO CON EL DISEÑO ESTABLECIDO.
F22: 140 | G22: =F22-SUM(H22:N22) -> 0 | H22: 0 | I22: 0 | J22: 0 | K22: 0 | L22: 76 | M22: 64 | N22: 0 | O22: 6º Trim | P22: 05 REALIZAR PRUEBAS AL SOFTWARE PARA VERIFICAR SU FUNCIONALIDAD.
C23: 220501098 | D23: 144 | E23: ADOPCIÓN DE BUENAS PRÁCTICAS EN EL PROCESO DE DESARROLLO DE SOFTWARE | F23: 48 | G23: =F23-SUM(H23:N23) -> 0 | H23: 0 | I23: 0 | J23: 0 | K23: 48 | L23: 0 | M23: 0 | N23: 0 | O23: 4º Trim | P23: 01 INCORPORAR ACTIVIDADES DE ASEGURAMIENTO DE LA CALIDAD DEL SOFTWARE DE ACUERDO CON ESTÁNDARES DE LA INDUSTRIA. | Q23: 3- IMPLEMENTACIÓN
F24: 48 | G24: =F24-SUM(H24:N24) -> 0 | H24: 0 | I24: 0 | J24: 0 | K24: 0 | L24: 48 | M24: 0 | N24: 0 | O24: 5º Trim | P24: 02 VERIFICAR LA CALIDAD DEL SOFTWARE DE ACUERDO CON LAS PRÁCTICAS ASOCIADAS EN LOS PROCESOS DE DESARROLLO.
F25: 48 | G25: =F25-SUM(H25:N25) -> 0 | H25: 0 | I25: 0 | J25: 0 | K25: 0 | L25: 0 | M25: 48 | N25: 0 | O25: 6º Trim | P25: 03 REALIZAR ACTIVIDADES DE MEJORA DE LA CALIDAD DEL SOFTWARE A PARTIR DE LOS RESULTADOS DE LA VERIFICACIÓN.
C26: 220501097 | D26: 144 | E26: IMPLANTACIÓN DEL SOFTWARE | F26: 36 | G26: =F26-SUM(H26:N26) -> 0 | H26: 0 | I26: 0 | J26: 0 | K26: 0 | L26: 0 | M26: 0 | N26: 36 | O26: 7º Trim | P26: 01 PLANEAR ACTIVIDADES DE IMPLANTACIÓN DEL SOFTWARE DE ACUERDO CON LAS CONDICIONES DEL SISTEMA. | Q26: 4- PRUEBAS / DESPLIEGUE
F27: 36 | G27: =F27-SUM(H27:N27) -> 0 | H27: 0 | I27: 0 | J27: 0 | K27: 0 | L27: 0 | M27: 0 | N27: 36 | O27: 7º Trim | P27: 02 DESPLEGAR EL SOFTWARE DE ACUERDO CON LA ARQUITECTURA Y LAS POLÍTICAS ESTABLECIDAS.
F28: 36 | G28: =F28-SUM(H28:N28) -> 0 | H28: 0 | I28: 0 | J28: 0 | K28: 0 | L28: 0 | M28: 36 | N28: 0 | O28: 6º Trim | P28: 03 DOCUMENTAR EL PROCESO DE IMPLANTACIÓN DE SOFTWARE SIGUIENDO ESTÁNDARES DE CALIDAD.
F29: 36 | G29: =F29-SUM(H29:N29) -> 0 | H29: 0 | I29: 0 | J29: 0 | K29: 0 | L29: 0 | M29: 36 | N29: 0 | O29: 6º Trim | P29: 04 IMPLANTAR EL SOFTWARE DE ACUERDO CON LOS NIVELES DE SERVICIO ESTABLECIDOS CON EL CLIENTE.
E30: TOTALES ÁREA TÉCNICA: | F30: =SUM(F3:F29) -> 2208 | G30: =SUM(G3:G29) -> 0 | H30: =SUM(H3:H29) -> 298 | I30: =SUM(I3:I29) -> 288 | J30: =SUM(J3:J29) -> 286 | K30: =SUM(K3:K29) -> 286 | L30: =SUM(L3:L29) -> 286 | M30: =SUM(M3:M29) -> 382 | N30: =SUM(N3:N29) -> 382
B32: INGLÉS Y AREÁ TRANSVERSAL | C32: 240202501 | D32: 384 | E32: INGLÉS | F32: 48 | G32: =F32-SUM(H32:N32) -> 0 | H32: 48 | I32: 0 | J32: 0 | K32: 0 | L32: 0 | M32: 0 | N32: 0 | O32: 1º Trim | P32: 01 COMPRENDER INFORMACIÓN SOBRE SITUACIONES COTIDIANAS Y LABORALES ACTUALES Y FUTURAS A TRAVÉS DE INTERACCIONES SOCIALES DE FORMA ORAL Y ESCRITA.
F33: 48 | G33: =F33-SUM(H33:N33) -> 0 | H33: 0 | I33: 0 | J33: 48 | K33: 0 | L33: 0 | M33: 0 | N33: 0 | O33: 3º Trim | P33: 02 INTERCAMBIAR OPINIONES SOBRE SITUACIONES COTIDIANAS Y LABORALES ACTUALES, PASADAS Y FUTURAS EN CONTEXTOS SOCIALES ORALES Y ESCRITOS.
F34: 48 | G34: =F34-SUM(H34:N34) -> 0 | H34: 0 | I34: 0 | J34: 0 | K34: 0 | L34: 0 | M34: 0 | N34: 48 | O34: 7º Trim | P34: 03 DISCUTIR SOBRE POSIBLES SOLUCIONES A PROBLEMAS DENTRO DE UN RANGO VARIADO DE CONTEXTOS SOCIALES Y LABORALES.
F35: 48 | G35: =F35-SUM(H35:N35) -> 0 | H35: 0 | I35: 0 | J35: 0 | K35: 48 | L35: 0 | M35: 0 | N35: 0 | O35: 4º Trim | P35: 04 IMPLEMENTAR ACCIONES DE MEJORA RELACIONADAS CON EL USO DE EXPRESIONES, ESTRUCTURAS Y DESEMPEÑO SEGÚN LOS RESULTADOS DE APRENDIZAJE FORMULADOS PARA EL PROGRAMA.
F36: =48*2 -> 96 | G36: =F36-SUM(H36:N36) -> 0 | H36: 0 | I36: 0 | J36: 0 | K36: 0 | L36: 48 | M36: 48 | N36: 0 | O36: 6º Trim | P36: 05 PRESENTAR UN PROCESO PARA LA REALIZACIÓN DE UNA ACTIVIDAD EN SU QUEHACER LABORAL DE ACUERDO CON LOS PROCEDIMIENTOS ESTABLECIDOS DESDE SU PROGRAMA DE FORMACIÓN.
F37: 48 | G37: =F37-SUM(H37:N37) -> 0 | H37: 0 | I37: 48 | J37: 0 | K37: 0 | L37: 0 | M37: 0 | N37: 0 | O37: 2º Trim | P37: 06 EXPLICAR LAS FUNCIONES DE SU OCUPACIÓN LABORAL USANDO EXPRESIONES DE ACUERDO AL NIVEL REQUERIDO POR EL PROGRAMA DE FORMACIÓN.
C38: 240201530 | D38: 48 | E38: INDUCCIÓN | F38: 48 | G38: =F38-SUM(H38:N38) -> 0 | H38: 48 | I38: 0 | J38: 0 | K38: 0 | L38: 0 | M38: 0 | N38: 0 | O38: 1º Trim | P38: 01 IDENTIFICAR LA DINÁMICA ORGANIZACIONAL DEL SENA Y EL ROL DE LA FORMACIÓN PROFESIONAL INTEGRAL DE ACUERDO CON SU PROYECTO DE VIDA Y EL DESARROLLO PROFESIONAL.
C39: 220501046 | D39: 48 | E39: TIC | F39: =48/4 -> 12 | G39: =F39-SUM(H39:N39) -> 0 | H39: 12 | I39: 0 | J39: 0 | K39: 0 | L39: 0 | M39: 0 | N39: 0 | O39: 1º Trim | P39: 01 ALISTAR HERRAMIENTAS DE TECNOLOGÍAS DE LA INFORMACIÓN Y LA COMUNICACIÓN (TIC), DE ACUERDO CON LAS NECESIDADES DE PROCESAMIENTO DE INFORMACIÓN Y COMUNICACIÓN.
F40: =48/4 -> 12 | G40: =F40-SUM(H40:N40) -> 0 | H40: 12 | I40: 0 | J40: 0 | K40: 0 | L40: 0 | M40: 0 | N40: 0 | O40: 1º Trim | P40: 02 APLICAR FUNCIONALIDADES DE HERRAMIENTAS Y SERVICIOS TIC, DE ACUERDO CON MANUALES DE USO, PROCEDIMIENTOS ESTABLECIDOS Y BUENAS PRÁCTICAS.
F41: =48/4 -> 12 | G41: =F41-SUM(H41:N41) -> 0 | H41: 12 | I41: 0 | J41: 0 | K41: 0 | L41: 0 | M41: 0 | N41: 0 | O41: 1º Trim | P41: 03 EVALUAR LOS RESULTADOS, DE ACUERDO CON LOS REQUERIMIENTOS
F42: =48/4 -> 12 | G42: =F42-SUM(H42:N42) -> 0 | H42: 12 | I42: 0 | J42: 0 | K42: 0 | L42: 0 | M42: 0 | N42: 0 | O42: 1º Trim | P42: 04 OPTIMIZAR LOS RESULTADOS, DE ACUERDO CON LA VERIFICACIÓN.
...

Sheet Trimestres
B2: 1º Trimestre | D2: Horas | F2: 2º Trimestre | H2: Horas
B3: C96-R01-Herramientas Dev | C3: Editores de Texto: Visual Studio Code, Emmet: Flujo de Trabajo, HTML: Lenguaje de etiquetas (4.01/5.0), Git: Sistema control del versiones | D3: 77 | F3: C96-R03-FronEnd | G3: CSS: Hojas de Estilo (2.1 / 3.0), PUG: Preprocesador HTML, SASS: Preprocesador CSS, Figma: Gráficos (Mapa de Bits / Vectoriales) | H3: 70
B4: C93-R03-Algorítmia | C4: Algoritmia(Lógica: solución de problemas) | D4: 77 | F4: C93-R01-Metodología | G4: Metodología ágil | H4: 71
B5: C92-Requerimientos | C5: Requerimientos (Funcionales y no funcionales) | D5: 144 | F5: C93-R02-UML_01 | G5: Diagramas Estructurales | H5: 70
F6: C96-R04-Codificar | G6: Javascript: Vanilla | H6: 77
B10: C-Ingles-R01 | C10: Reading-Writing | D10: 48
B11: C-Matemáticas | C11: Lógica matemática | D11: 48 | F11: C-Ingles-R06 | G11: Reading-Writing | H11: 48
B12: C-TIC | C12: Teoría general de sistemas | D12: 48 | F12: C-Investigación | G12: Recolección de información y técnicas | H12: 48
B13: C-Inducción | C13: Gestión Tecnológica | D13: 48 | F13: C-Física | G13: Conceptos básicos | H13: 48
D14: =SUM(D3:D13)&" Horas" -> 490 Horas | H14: =SUM(H3:H13)&" Horas" -> 432 Horas
B16: 3º Trimestre | D16: Horas | F16: 4º Trimestre | H16: Horas
B17: TypeScript | C17: TypeScript Preprocesador de Javascript | F17: C-95-R03- Vue JS / React / Svelte | G17: Vue JS / React / Svelte Framework Javascript | H17: 84
B18: C-95-R01-jQuery | C18: jQuery Libreria Javascript | D18: 84 | F18: C-94-R02-Electron JS | G18: Electron JS Contrucción Apps de escritorio | H18: 48
B19: C-95-R02-Bootstrap | C19: Bootstrap Framework CSS | D19: 84 | F19: C-96-R02-Flask | G19: Flask Framework Python | H19: 50
B20: C-94-R01-Tailwind | C20: Tailwind Framework CSS | D20: 48 | F20: C-96-R04-C # | G20: C # Aplicaciones Stand Alone | H20: 56
B21: AMP | C21: AMP(Apache, MariaDB, PHP) | F21: C-98-R01-PHP (POO) | G21: PHP (POO) Programación orientada a objetos | H21: 48
B22: PHP (Básico/Intermedio) | C22: PHP (Básico/Intermedio) Lenguaje de programación (Server-Side) | F22: PHP (MVC) | G22: PHP (MVC) Modelo de 3 Capas
B23: Python | C23: Python Lenguaje de programación | F23: PHP (PDO) MySQL/Maria DB | G23: PHP (PDO) MySQL/Maria DB Gestor de base de datos relacionales
B24: SQL (Bases de Datos) | C24: SQL (Bases de Datos) Lenguaje de consultas | F24: Netlify/Vercel | G24: Netlify/Vercel Despliegue de Apps
B25: MarkDown | C25: MarkDown
B26: C93-R04-UML_02 | C26: Lenguaje unificado de modelado | D26: 70
B27: C-Ingles-R02 | C27: Reading-Writing | D27: 48 | F27: C-Ingles-R04 | G27: Reading-Writing | H27: 48
B28: Comunicación | D28: 48 | F28: Protección para la salud y el medio ambiente | H28: 48
B29: Ética | D29: 48 | F29: Actividad física | H29: 48
D30: =SUM(D17:D29)&" Horas" -> 430 Horas | H30: =SUM(H17:H29)&" Horas" -> 430 Horas
B32: 5º Trimestre | D32: Horas | F32: 6º Trimestre | H32: Horas
B33: C-95-R04-Laravel | C33: Framework PHP | D33: 84 | F33: C-96-R01-Flutter/Ionic | G33: Desarrollo móviles | H33: 31
B34: C-94-R03-Django | C34: Framework Python | D34: 48 | F34: C-96-R02-Heroku | G34: Plataforma como un servicio | H34: 30
B35: C-96-R02-API Rest | C35: Creación y consumo de servicios | D35: 30 | F35: C-96-R03-Mongo DB / Redis | G35: Base de datos no relacional | H35: 45
B36: C-96-R05-Wordpress | C36: CMS - Gestor de contenidos | D36: 76 | F36: C-96-R04-Kotlin | G36: Desarollo android | H36: 92
B37: C-98-R02 | D37: 48 | F37: C-96-R05 | H37: 64
F38: C-98-R03 | H38: 48
F39: C-97-R03 | H39: 36
F40: C-97-R04 | H40: 36
B41: C-Ingles-R05 | C41: Reading-Writing | D41: 48
B42: Cultura emprendedora | D42: 48
B43: Ejercer derechos fundamentales | D43: 48 | F43: C-Ingles-R05 | G43: Reading-Writing | H43: 48
D44: =SUM(D32:D43)&" Horas" -> 430 Horas | H44: =SUM(H32:H43)&" Horas" -> 430 Horas
B47: 7º Trimestre | D47: Horas
B48: C-96-R01-Proyecto formativo | C48: Desarrollo y entrega de producto | D48: 32
...

Sheet Conocimientos
B2: Competencia | C2: Saber
B3: Adopción | C3: * FUNDAMENTOS DE CALIDAD: CONCEPTOS, GESTIÓN DE PROCESOS, * ESTÁNDARES DE CALIDAD PARA EL DESARROLLO DE SOFTWARE: CONJUNTO DE NORMAS ISO/IEC 25000 SQUARE, ISO/IEC 15504, IEEE. * MODELOS DE CALIDAD DE SOFTWARE: CMMI * METODOLOGÍAS DE DESARROLLO: ÁGILES, TRADICIONALES * DISCIPLINAS DE CALIDAD DE SOFTWARE: PSP FUNDAMENTALS, TSP * ADMINISTRACIÓN DEL PROCESO PERSONAL DE CONSTRUCCIÓN DE SOFTWARE: FUNDAMENTOS, PRINCIPIOS, NIVELES, SCRIPTS, FORMAS, ESTÁNDARES, DOCUMENTACIÓN, MÉTODO PROBE, ESTADÍSTICAS, HERRAMIENTAS INFORMÁTICAS DE APOYO. * DOCUMENTACIÓN: FORMATOS, PLANTILLAS, ESTÁNDARES DE DOCUMENTACIÓN DE PROCESOS DE CALIDAD.
B4: Construcción | C4: PLANEAR ACTIVIDADES DE CONSTRUCCIÓN DEL SOFTWARE DE ACUERDO CON EL DISEÑO ESTABLECIDO: * INFORME DE DISEÑO: INTERPRETACIÓN, ANÁLISIS. * HERRAMIENTAS DE APOYO: VERSIONAMIENTO, CONTROL DE CAMBIOS DEL CÓDIGO, INTEGRACIÓN CONTINUA. * ESTÁNDARES DE CODIFICACIÓN: PLANTILLA DE ESTÁNDAR DE CÓDIGO, (DOCUMENTACIÓN DE CÓDIGO, REGLAS DE NOMBRADO PARA VARIABLES, MÉTODOS, ATRIBUTOS, CLASES, TABLAS, CAMPOS, INDENTACIÓN). CONSTRUIR LA BASE DE DATOS PARA EL SOFTWARE A PARTIR DEL MODELO DE DATOS: * MOTORES DE BASES DE DATOS RELACIONALES (ORACLE, SQL SERVER, POSTGRESQL, MYSQL, MARIADB, SQLITE): CONCEPTOS DE SISTEMA MANEJADOR DE BASES DE DATOS - SMBD, LICENCIAMIENTO, INSTALACIÓN, INSTANCIAS, CONFIGURACIÓN, SISTEMA DE ARCHIVOS, OBJETOS DE LA BD (TABLAS, RELACIONES, ÍNDICES, VISTAS, PROCEDIMIENTOS ALMACENADOS, RESTRICCIONES), SEGURIDAD DE LA INFORMACIÓN, PERMISOS, COPIAS DE SEGURIDAD, RESTAURACIÓN DE LA BD. * NOSQL: (REDIS, MONGODB): CONCEPTOS, INSTALACIÓN, CONSULTAS, DOCUMENTOS, COLECCIONES, OBJETOS. * SQL: SENTENCIAS DDL (CREATE, ALTER, DROP, TRUNCATE), DML (SELECT, INSERT, UPDATE, DELETE, MERGE), DCL (REVOKE, GRANT), CONTROL DE TRANSACCIONES (COMMIT, ROLLBACK), PROGRAMACIÓN EN SQL (CURSORES, PROCEDIMIENTOS, FUNCIONES, TRIGGERS). CREAR COMPONENTES FRONT-END DEL SOFTWARE DE ACUERDO CON EL DISEÑO: * INTERFAZ GRÁFICA EN APLICACIONES DE ESCRITORIO: FORMULARIOS, OBJETOS DE UN FORMULARIO, CUADROS DE DIALOGO, MENÚS, BARRAS DE HERRAMIENTAS. * INTERFAZ GRÁFICA EN APLICACIONES WEB: CONCEPTO, MANEJO DE ETIQUETAS, FORMULARIOS, COMPONENTES DEL FORMULARIO, DISTRIBUCIÓN, W3C, VALIDADOR W3C, FRAMEWORK FRONT-END (BOOTSTRAP). * HOJAS DE ESTILO: CONCEPTOS, SINTAXIS, USOS. * JAVASCRIPT: SINTAXIS, LIBRERÍAS(JQUERY, MODERNIZR), FRAMEWORKS (ANGULARJS, PROTOTYPE, MOOTOOLS). * GESTORES DE CONTENIDOS: CONCEPTOS, TIPOS, USO (WORDPRESS, JOOMLA). * INTERFAZ GRÁFICA EN APLICACIONES MÓVILES: DISPOSITIVOS, PLATAFORMAS, ORGANIZACIÓN DE CONTENIDOS, VISTAS, FRAMEWORKS PARA DESARROLLO MÓVIL. CODIFICAR EL SOFTWARE DE ACUERDO CON EL DISEÑO ESTABLECIDO: * LENGUAJE DE PROGRAMACIÓN ORIENTADO A OBJETOS: C#, JAVA (SE, EE), PHP, PYTHON, RUBY. CONCEPTOS ASOCIADOS AL LENGUAJE, ANTECEDENTES, IDE, SINTAXIS, ESTRUCTURA GENERAL DEL LENGUAJE (ESTÁNDAR DE CÓDIGO), APLICACIONES, CLIENTES PERSONALIZADOS PARA CONEXIÓN A LAS BASES DE DATOS (CADENAS DE CONEXIÓN), GENERACIÓN DE REPORTES. * EDITORES DE CÓDIGO: CARACTERÍSTICAS, INSTALACIÓN, USO (VISUAL STUDIO CODE, SUBLIME TEXT, ATOM, BRACKETS, NOTEPAD ++). * ENTORNOS DE DESARROLLO / FRAMEWORKS: CARACTERÍSTICAS, INSTALACIÓN, USO (NETBEANS, VISUAL STUDIO .NET, ECLIPSE, ANACONDA, LARAVEL, RUBY ON RAILS, DJANGO, VAADIN). * SEGURIDAD: SQL INJECTION, ALGORITMOS DE ENCRIPTACIÓN, FIRMAS DIGITALES, MANEJO DE SESIONES. * SERVIDORES DE APLICACIONES / SERVIDORES WEB: DEFINICIONES, TIPOS, USOS (GLASSFISH, APACHE, IIS, NODE.JS) * SERVICIOS WEB: CONCEPTO, TIPOS (SOAP, RESTFUL), FORMATO INTERCAMBIO DE DATOS (JSON, XML). * CLOUD COMPUTING: CONCEPTO, DESARROLLO EN LA NUBE (PLATAFORMAS AZURE, AWS, HEROKU, EDITORES CLOUD9, FUNCIÓN COMO SERVICIO FAAS AWS LAMBDA). * CREACIÓN DE APP: CONCEPTO, PLATAFORMAS NATIVAS (ANDROID, IOS), SQLITE, LIBRERÍAS DE TERCEROS. * ENTORNOS DE DESARROLLO MÓVIL: CONCEPTO, PLATAFORMAS (KOTLIN, SWIFT, IONIC) * INTERNET DE LAS COSAS: INTRODUCCIÓN, APLICACIONES, DESARROLLOS. * BLOCKCHAIN: INTRODUCCIÓN, APLICACIONES, DESARROLLOS. * MACHINE LEARNING: CONCEPTOS, APLICACIONES, DEEP LEARNING. * CONTROL DE VERSIONES: HERRAMIENTAS PARA CONTROL DE CAMBIOS EN EL CÓDIGO (GIT, GITHUB, APACHE SUBVERSION). REALIZAR PRUEBAS AL SOFTWARE PARA VERIFICAR SU FUNCIONALIDAD: * PRUEBAS: CONCEPTOS, NIVELES, TIPOS, ENFOQUES, PLAN DE PRUEBAS, DISEÑO DE CASOS DE PRUEBA, HERRAMIENTAS TECNOLÓGICAS PARA PRUEBAS, DOCUMENTACIÓN DE PRUEBAS (UNITARIAS, CARGA, ESTRÉS, INTEGRACIÓN). * DESARROLLO GUIADO POR PRUEBAS (TDD): METODOLOGÍAS ÁGILES, CODIFICACIÓN Y PRUEBAS.
B5: Modelado | C5: ELABORAR LOS ARTEFACTOS DE DISEÑO DEL SOFTWARE SIGUIENDO LAS PRÁCTICAS DE LA METODOLOGÍA SELECCIONADA: * INFORME DE ANÁLISIS: INTERPRETACIÓN, ANÁLISIS Y TOMA DE DECISIONES. * DISEÑO ORIENTADO A OBJETOS: CONCEPTOS (COHESIÓN, ACOPLAMIENTO, ENCAPSULAMIENTO, POLIMORFISMO, COMPOSICIÓN, HERENCIA, INTERFACES), PRINCIPIOS (ADAPTABILIDAD, EXTENSIBILIDAD, MANTENIBILIDAD, REUSABILIDAD, DESEMPEÑO, ESCALABILIDAD, CONFIABILIDAD, EFICIENCIA). * PLATAFORMAS TECNOLÓGICAS: MOTORES DE BASES DE DATOS RELACIONALES, NO RELACIONALES, LENGUAJES DE PROGRAMACIÓN CON ORIENTACIÓN A OBJETOS. * DIAGRAMA DE CLASES: ATRIBUTOS, MÉTODOS, RELACIONES. * PATRONES DE DISEÑO (GOF): CONCEPTOS, COMPORTAMENTALES (ESTRATEGIA, COMANDO, ITERADOR), CREACIONALES (SINGLETON, FÁBRICA ABSTRACTA), ESTRUCTURALES (FACHADA). * ARQUITECTURA DE SOFTWARE: GENERALIDADES, CONCEPTOS, TIPOS DE ARQUITECTURAS, COMPONENTES, VISTAS Y MODELOS RELACIONADOS, CUALIDADES SISTÉMICAS. * ARQUITECTURA ORIENTADA A SERVICIOS (SOA, REST, GRAPHQL): CONCEPTOS, APLICACIONES. * ARQUITECTURAS MICROSERVICES Y SERVERLESS: CONCEPTOS, APLICACIONES. * DEVOPS, INTEGRACIÓN CONTINUA: CONCEPTOS, APLICACIONES. * ARQUITECTURA CLIENTE / SERVIDOR: CONCEPTO, 2 CAPAS, 3 CAPAS, N CAPAS, APLICACIONES DISTRIBUIDAS, CLIENTES MÓVILES, CONCEPTOS ARQUITECTURA REST. * MODELO VISTA CONTROLADOR: CONCEPTO, APLICACIÓN * VISTA DE COMPONENTES: DIAGRAMA DE COMPONENTES. * VISTA FÍSICA: DIAGRAMA DE DESPLIEGUE. * DOCUMENTO DE DISEÑO: MODELOS, ARQUITECTURA CANDIDATA. ESTRUCTURAR EL MODELO DE DATOS DEL SOFTWARE DE ACUERDO CON LAS ESPECIFICACIONES DEL ANÁLISIS: * MODELO LÓGICO DE DATOS (MODELO RELACIONAL): CONCEPTO, REPRESENTACIÓN, CARDINALIDAD, REGLAS DE TRANSFORMACIÓN DE MODELO CONCEPTUAL A MODELO LÓGICO, RESTRICCIONES, HERRAMIENTAS PARA EL DISEÑO DE BASE DE DATOS. * BASES DE DATOS: CONCEPTOS, CARACTERÍSTICAS, RELACIONALES, NO RELACIONALES, MOTORES. * DICCIONARIO DE DATOS: TIPO DE DATOS, TAMAÑO DE LOS DATOS, ESTÁNDARES DE NOMBRADO, RESTRICCIONES Y DOMINIO DE DATOS. * NORMALIZACIÓN: CONCEPTOS, FORMAS NORMALES, EJEMPLOS. * SEGURIDAD DE LA INFORMACIÓN: CONCEPTO, POLÍTICAS, ENCRIPTACIÓN DE DATOS, TRATAMIENTO DE DATOS PERSONALES, NIVELES DE ACCESO. * BIG DATA: CONCEPTOS, APLICACIONES. DETERMINAR LAS CARACTERÍSTICAS TÉCNICAS DE LA INTERFAZ GRÁFICA DEL SOFTWARE ADOPTANDO ESTÁNDARES: * COMPONENTE GRÁFICO: CONCEPTOS, CARACTERÍSTICAS, TEORÍA DEL COLOR, USABILIDAD, ACCESIBILIDAD, FRAMEWORK FRONT-END, W3C, WEB SEMÁNTICA. * DISEÑO DE INTERFAZ PARA DISPOSITIVOS MÓVILES: CONCEPTOS, DISPOSITIVOS, CARACTERÍSTICAS, REGLAS DE DISEÑO. * TIPOS DE PROTOTIPADO: CONCEPTOS, TÉCNICAS (BOCETOS, MAPAS DE NAVEGACIÓN, PROTOTIPOS EN PAPEL, PROTOTIPOS DE SOFTWARE), HERRAMIENTAS DE APOYO, PROTOTIPADO PARA APLICACIONES WEB, STAND-ALONE Y MÓVILES. VERIFICAR LOS ENTREGABLES DE LA FASE DE DISEÑO DEL SOFTWARE DE ACUERDO CON LO ESTABLECIDO EN EL INFORME DE ANÁLISIS: * TÉCNICAS DE EVALUACIÓN: INSPECCIÓN, REVISIÓN. * LISTAS DE CHEQUEO: CRITERIOS DE ACEPTACIÓN. * PRÁCTICAS DE DISEÑO: BAJO ACOPLAMIENTO Y ALTA COHESIÓN. * INFORME DE DISEÑO: CONCEPTO, CARACTERÍSTICAS, ARTEFACTOS ELABORADOS EN LA FASE DE DISEÑO.
B6: Especificación | C6: CARACTERIZAR LOS PROCESOS DE LA ORGANIZACIÓN DE ACUERDO CON EL SOFTWARE A CONSTRUIR: * TEORÍA GENERAL DE SISTEMAS: ORÍGENES, CONCEPTOS. * ENFOQUE SISTÉMICO: CONCEPTO, CARACTERÍSTICAS, APLICACIÓN, ORGANIZACIONES INTELIGENTES. * DATOS E INFORMACIÓN: CONCEPTOS DATOS E INFORMACIÓN, PROCESAMIENTO DE DATOS Y ACTIVIDADES DE PROCESAMIENTO DE DATOS. * SISTEMAS DE INFORMACIÓN: ELEMENTOS, OBJETIVOS, CLASIFICACIÓN. * CICLO DE VIDA DEL SOFTWARE: DEFINICIÓN, ELEMENTOS, MODELOS, FASES Y SUS OBJETIVOS. * METODOLOGÍAS DE DESARROLLO: CONCEPTOS, TIPOS. * PROCESOS: DEFINICIÓN, CARACTERÍSTICAS, ENTRADAS, COMPONENTES, REPRESENTACIÓN GRÁFICA, PROCEDIMIENTOS, MODELO DE PROCESOS DE NEGOCIO (BPM). RECOLECTAR INFORMACIÓN DEL SOFTWARE A CONSTRUIR DE ACUERDO CON LAS NECESIDADES DEL CLIENTE: * TÉCNICAS DE ELICITACIÓN DE REQUISITOS: TÉCNICAS DE PROSPECCIÓN, TÉCNICAS DE CREATIVIDAD, TÉCNICAS CENTRADAS EN LA DOCUMENTACIÓN, TÉCNICAS DE OBSERVACIÓN. * REQUISITOS: CONCEPTOS, REQUISITOS FUNCIONALES Y NO FUNCIONALES. * INGENIERÍA DE REQUISITOS: ANÁLISIS DE REQUISITOS, GESTIÓN DE REQUISITOS, PRÁCTICAS ÁGILES(HISTORIAS DE USUARIOS, ITERACIONES, PRODUCT BACKLOG, ESTIMACIONES, STORYBOARD)". * ESTADÍSTICA DESCRIPTIVA: DEFINICIÓN, POBLACIÓN, ELEMENTOS Y CARACTERÍSTICAS, VARIABLES CUALITATIVAS Y CUANTITATIVAS, MEDIDAS DE TENDENCIAS CENTRAL (MEDIA, MEDIA GEOMÉTRICA, MEDIANA, MODA), REPRESENTACIÓN GRÁFICA DE LOS DATOS. * FUENTES DE REQUISITOS: IMPLICADOS, DOCUMENTACIÓN, SISTEMAS EN OPERACIÓN.
B7: Elaboración | C7: DEFINIR ESPECIFICACIONES TÉCNICAS DEL SOFTWARE DE ACUERDO CON LAS CARACTERÍSTICAS DEL SOFTWARE A CONSTRUIR: * TECNOLOGÍA INFORMÁTICA: CARACTERÍSTICAS DE HARDWARE Y SOFTWARE, TENDENCIAS DE FABRICACIÓN TI Y MERCADO EN EL ÁMBITO NACIONAL E INTERNACIONAL. * SOLUCIONES INFORMÁTICAS: DIAGNÓSTICO DE NECESIDADES Y ELABORACIÓN DE REFERENTES TÉCNICOS. * GESTIÓN TECNOLÓGICA: CONCEPTOS Y CARACTERÍSTICAS, INNOVACIÓN, EMPRENDIMIENTO Y ACTIVIDADES DE LA GESTIÓN TECNOLÓGICA. * CONTRATACIÓN DE SERVICIOS DE TI: CONCEPTO, TIPOS, PRINCIPIOS Y CARACTERÍSTICAS, NORMATIVIDAD GENERAL DE LA CONTRATACIÓN TANTO PRIVADA COMO ESTATAL. * PROYECTOS DE TI: TIPOS, CARACTERÍSTICAS, FASES. * LICENCIAMIENTO DE SOFTWARE: CONCEPTO, TIPOS, CARACTERÍSTICAS, DIFERENCIAS DE CARÁCTER TÉCNICO Y DE CONDICIONES DE CUMPLIMIENTO * PROPIEDAD INTELECTUAL: DERECHOS DE AUTOR, PROPIEDAD INDUSTRIAL, REGISTRO DE SOFTWARE. ELABORAR PROPUESTA TÉCNICA DEL SOFTWARE DE ACUERDO CON LAS ESPECIFICACIONES TÉCNICAS DEFINIDAS: * COSTOS: CONCEPTOS, FUNDAMENTOS, CLASIFICACIÓN. SOFTWARE. * FICHA TÉCNICA: ELEMENTOS MÍNIMOS PARA DESCRIBIR LOS REFERENTES TÉCNICOS. * TÉRMINOS DE REFERENCIA: CONCEPTO, ELEMENTOS Y CONSTRUCCIÓN. VALIDAR LAS CONDICIONES DE LA PROPUESTA TÉCNICA DEL SOFTWARE DE ACUERDO CON LOS INTERESES DE LAS PARTES: * COMUNICACIÓN: TÉCNICAS, TIPOS Y HABILIDADES. * NEGOCIACIÓN DE TECNOLOGÍA: ESTILOS DE NEGOCIACIÓN, PRINCIPIOS DE NEGOCIACIÓN, IDENTIFICACIÓN Y SOLUCIÓN DE CONFLICTOS. * CONTRATO: CONCEPTO, TIPOS, PARTES, NORMATIVIDAD * ACUERDOS DE NIVELES DE SERVICIO: CONCEPTO, FORMULACIÓN, MÉTRICAS.
B8: Análisis | C8: PLANEAR ACTIVIDADES DE ANÁLISIS DE ACUERDO CON LA METODOLOGÍA SELECCIONADA: * METODOLOGÍAS DE DESARROLLO DE SOFTWARE: CONCEPTO, CLASIFICACIÓN, ROLES, EJEMPLOS. * METODOLOGÍAS TRADICIONALES: PROCESO UNIFICADO RACIONAL (RUP) * METODOLOGÍAS ÁGILES: SCRUM, PROGRAMACIÓN EXTREMA (XP), DESARROLLO RÁPIDO DE APLICACIONES (RAD). * PROYECTOS DE SOFTWARE: CARACTERÍSTICAS, TIPOS, COMPONENTES. * PLANEACIÓN: DEFINIR Y PRIORIZAR ACTIVIDADES DE ANÁLISIS, FIJAR CRONOGRAMAS Y ENTREGABLES. MODELAR LAS FUNCIONES DEL SOFTWARE DE ACUERDO CON EL INFORME DE REQUISITOS: * INFORMES DE REQUISITOS: ANÁLISIS, INTERPRETACIÓN Y TOMA DE DECISIONES. * ANÁLISIS ORIENTADO A OBJETOS: CONCEPTOS DE OBJETO, CLASE, INSTANCIA, MULTIPLICIDAD, ASOCIACIÓN, AGREGACIÓN, COMPOSICIÓN, ACTOR, CASO DE USO, MENSAJES, EXCEPCIONES, CONDICIONES, POST-CONDICIONES, FOCOS DE CONTROL. * UML: DEFINICIÓN, NOTACIÓN, ELEMENTOS, RELACIONES, DIAGRAMAS, CLASIFICACIÓN. * DIAGRAMAS UML: CASOS DE USO, ACTIVIDADES, MODELO DE DOMINIO. * HERRAMIENTAS CASE: DEFINICIÓN, TIPOS, USO. * MODELO DE DATOS: FUNDAMENTOS DE BASES DE DATOS, MODELO ENTIDAD RELACIÓN. DESARROLLAR PROCESOS LÓGICOS A TRAVÉS DE LA IMPLEMENTACIÓN DE ALGORITMOS: * LÓGICA MATEMÁTICA: FUNDAMENTOS, LÓGICA PROPOSICIONAL. * ALGORITMO: CONCEPTO, TIPOS, TÉCNICAS PARA LA FORMULACIÓN DE ALGORITMOS (PSEUDOCÓDIGO, DIAGRAMAS DE FLUJO), ENTIDADES PRIMITIVAS, JERARQUÍA DE OPERADORES, ESTRUCTURAS SECUENCIALES, CONDICIONALES, CÍCLICAS, ARREGLOS, FUNCIONES, PROCEDIMIENTOS, PRUEBA DE ESCRITORIO. * HERRAMIENTAS PARA CREACIÓN Y PRUEBA DE ALGORITMOS: DFD, LPP O PSEINT, PYTHON. VERIFICAR LOS MODELOS REALIZADOS EN LA FASE DE ANÁLISIS DE ACUERDO CON LO ESTABLECIDO EN EL INFORME DE REQUISITOS: * INFORME DE ANÁLISIS: ESTRUCTURA, RESULTADOS. * INSTRUMENTOS DE VERIFICACIÓN: LISTAS DE CHEQUEO. * TRAZABILIDAD: ARTEFACTOS GENERADOS EN EL ANÁLISIS FRENTE A LOS REQUISITOS.
B9: Implantación | C9: PLANEAR ACTIVIDADES DE IMPLANTACIÓN DEL SOFTWARE DE ACUERDO CON LAS CONDICIONES DEL SISTEMA: * HARDWARE DE SERVIDORES: RACK, BLADE, ARREGLOS DE DISCOS. * SOFTWARE DE SERVIDORES: TIPOS, CARACTERÍSTICAS, LICENCIAMIENTO, MÁQUINAS VIRTUALES (VMWARE), SERVIDORES DE BASES DE DATOS. * MIGRACIÓN DE DATOS: CONCEPTO, PLANES, COPIAS DE SEGURIDAD, PROCESOS DE RESTAURACIÓN. * SISTEMAS OPERATIVOS DE SERVIDORES: CONCEPTO, CARACTERÍSTICAS, TIPOS (LINUX, WINDOWS SERVER), LICENCIAMIENTO, REQUISITOS MÍNIMOS DE INSTALACIÓN. * HOSTING Y DOMINIO: TIPOS, CONFIGURACIONES, GESTORES DE CONTENIDOS. * FTP: CONCEPTO, TRANSFERENCIA DE ARCHIVOS. DESPLEGAR EL SOFTWARE DE ACUERDO CON LA ARQUITECTURA Y LAS POLÍTICAS ESTABLECIDAS: * CONTEXTO DEL AMBIENTE DE PRODUCCIÓN: UBICACIÓN DE LOS SERVIDORES, SISTEMA OPERATIVO DE RED, POLÍTICAS DE SEGURIDAD, CONFIGURACIÓN DEL SISTEMA (SERVIDORES, CLIENTES). * DISTRIBUCIÓN DEL SOFTWARE: PROCEDIMIENTO DE LIBERACIÓN DEL SOFTWARE, ORGANIZACIÓN DE ARCHIVOS * CLOUD COMPUTING: CONCEPTOS, DISEÑO, TECNOLOGÍAS Y PRINCIPALES HERRAMIENTAS PARA TRABAJAR EN LA NUBE, AZURE, AWS, HEROKU, NODE.JS, SERVICIOS Y PROVEEDORES CLOUD DE RELEVANCIA, COSTOS. DOCUMENTAR EL PROCESO DE IMPLANTACIÓN DE SOFTWARE SIGUIENDO ESTÁNDARES DE CALIDAD: * MANUALES: TIPOS (TÉCNICO, USUARIO E INSTALACIÓN), AYUDAS EN LÍNEA, TÉCNICAS DE PRESENTACIÓN DE TRABAJOS ESCRITOS, NORMAS ICONTEC / APA, REDACCIÓN, ORTOGRAFÍA. * INFORMES TÉCNICOS: DEFINICIÓN, CARACTERÍSTICAS, CONTENIDO. IMPLANTAR EL SOFTWARE DE ACUERDO CON LOS NIVELES DE SERVICIO ESTABLECIDOS CON EL CLIENTE: * CAPACITACIÓN: TÉCNICAS DE COMUNICACIÓN ORAL, PLANES DE CAPACITACIÓN Y ELABORACIÓN DE MATERIALES DE APOYO. * ACTAS DE ENTREGA: FORMATO, DILIGENCIAMIENTO

Sheet Resultado  Filtro
B2: Código Norma | C2: Competencia | D2: Horas | E2: Resultados | F2: Nombre Corto | G2: Ciclo SW | H2: Trimestre Ini | I2: Trimestre Fin | J2: HORAS TEC TRIM | K2: HORAS TRANS | L2: TOTAL HORAS
B3: 220501092 | C3: ESPECIFICACIÓN DE REQUISITOS DEL SOFTWARE | D3: 36 | E3: 02 RECOLECTAR INFORMACIÓN DEL SOFTWARE A CONSTRUIR DE ACUERDO CON LAS NECESIDADES DEL CLIENTE. | F3: C92-R02-Requerimientos | G3: 0- REQUISITOS | H3: 1º Trimestre | I3: 1º Trimestre | J3: =SUM(D3:D8) -> 298 | K3: =SUM(Trimestres!D10:D13) -> 192 | L3: =SUM(J3,K3)&" horas" -> 490 horas | M3: I
B4: 220501092 | C4: ESPECIFICACIÓN DE REQUISITOS DEL SOFTWARE | D4: 36 | E4: 04 VALIDAR EL INFORME DE REQUISITOS DE ACUERDO CON LAS NECESIDADES DEL CLIENTE. | F4: C92-R04-Requerimientos | G4: 0- REQUISITOS | H4: 1º Trimestre | I4: 1º Trimestre
B5: 220501092 | C5: ESPECIFICACIÓN DE REQUISITOS DEL SOFTWARE | D5: 36 | E5: 01 CARACTERIZAR LOS PROCESOS DE LA ORGANIZACIÓN DE ACUERDO CON EL SOFTWARE A CONSTRUIR. | F5: C92-R01-Requerimientos | G5: 0- REQUISITOS | H5: 1º Trimestre | I5: 1º Trimestre
B6: 220501092 | C6: ESPECIFICACIÓN DE REQUISITOS DEL SOFTWARE | D6: 36 | E6: 03 ESTABLECER LOS REQUISITOS DEL SOFTWARE DE ACUERDO CON LA INFORMACIÓN RECOLECTADA. | F6: C92-R03-Requerimientos | G6: 0- REQUISITOS | H6: 1º Trimestre | I6: 1º Trimestre
B7: 220501093 | C7: ANÁLISIS DE LA ESPECIFICACIÓN DE REQUISITOS DEL SOFTWARE | D7: 77 | E7: 03 DESARROLLAR PROCESOS LÓGICOS A TRAVÉS DE LA IMPLEMENTACIÓN DE ALGORITMOS. | F7: C93-R03-Algorítmia | G7: 1- ANÁLISIS | H7: 1º Trimestre | I7: 1º Trimestre
B8: 220501096 | C8: CONSTRUCCIÓN DEL SOFTWARE | D8: 77 | E8: 01 PLANEAR ACTIVIDADES DE CONSTRUCCIÓN DEL SOFTWARE DE ACUERDO CON EL DISEÑO ESTABLECIDO. | F8: C96-R01-Herramientas Dev | G8: 3- IMPLEMENTACIÓN | H8: 1º Trimestre | I8: 2º Trimestre
B9: 220501096 | C9: CONSTRUCCIÓN DEL SOFTWARE | D9: 70 | E9: 03 CREAR COMPONENTES FRONT-END DEL SOFTWARE DE ACUERDO CON EL DISEÑO. | F9: C96-R03-FronEnd | G9: 3- IMPLEMENTACIÓN | H9: 2º Trimestre | I9: 7º Trimestre | J9: =SUM(D9:D12) -> 311 | K9: =SUM(Trimestres!H11:H13) -> 144 | L9: =SUM(J9,K9)&" horas" -> 455 horas | M9: II
B10: 220501093 | C10: ANÁLISIS DE LA ESPECIFICACIÓN DE REQUISITOS DEL SOFTWARE | D10: 70 | E10: 02 MODELAR LAS FUNCIONES DEL SOFTWARE DE ACUERDO CON EL INFORME DE REQUISITOS. | F10: C93-R02-UML | G10: 1- ANÁLISIS | H10: 2º Trimestre | I10: 2º Trimestre
B11: 220501093 | C11: ANÁLISIS DE LA ESPECIFICACIÓN DE REQUISITOS DEL SOFTWARE | D11: 71 | E11: 01 PLANEAR ACTIVIDADES DE ANÁLISIS DE ACUERDO CON LA METODOLOGÍA SELECCIONADA. | F11: C93-R01-Metodología | G11: 1- ANÁLISIS | H11: 2º Trimestre | I11: 2º Trimestre
B12: 220501096 | C12: CONSTRUCCIÓN DEL SOFTWARE | D12: 100 | E12: 04 CODIFICAR EL SOFTWARE DE ACUERDO CON EL DISEÑO ESTABLECIDO. | F12: C96-R04-Codificar | G12: 3- IMPLEMENTACIÓN | H12: 2º Trimestre | I12: 7º Trimestre
B13: 220501093 | C13: ANÁLISIS DE LA ESPECIFICACIÓN DE REQUISITOS DEL SOFTWARE | D13: 70 | E13: 04 VERIFICAR LOS MODELOS REALIZADOS EN LA FASE DE ANÁLISIS DE ACUERDO CON LO ESTABLECIDO EN EL INFORME DE REQUISITOS. | F13: C93-R04-UML | G13: 1- ANÁLISIS | H13: 3º Trimestre | I13: 3º Trimestre | J13: =SUM(D13:D16) -> 286 | K13: =SUM(Trimestres!D27:D29) -> 144 | L13: =SUM(J13,K13)&" horas" -> 430 horas | M13: III
B14: 220501095 | C14: MODELADO DE LOS ARTEFACTOS DEL SOFTWARE | D14: 84 | E14: 02 ESTRUCTURAR EL MODELO DE DATOS DEL SOFTWARE DE ACUERDO CON LAS ESPECIFICACIONES DEL ANÁLISIS. | F14: C95-R02 | G14: 2- DISEÑO | H14: 3º Trimestre | I14: 3º Trimestre
B15: 220501095 | C15: MODELADO DE LOS ARTEFACTOS DEL SOFTWARE | D15: 84 | E15: 01 ELABORAR LOS ARTEFACTOS DE DISEÑO DEL SOFTWARE SIGUIENDO LAS PRÁCTICAS DE LA METODOLOGÍA SELECCIONADA. | F15: C95-R01 | G15: 2- DISEÑO | H15: 3º Trimestre | I15: 3º Trimestre
B16: 220501094 | C16: ELABORACIÓN DE LA PROPUESTA TÉCNICA DEL SOFTWARE | D16: 48 | E16: 01 DEFINIR ESPECIFICACIONES TÉCNICAS DEL SOFTWARE DE ACUERDO CON LAS CARACTERÍSTICAS DEL SOFTWARE A CONSTRUIR. | F16: C94-R01 | G16: 2- DISEÑO | H16: 3º Trimestre | I16: 3º Trimestre
B17: 220501094 | C17: ELABORACIÓN DE LA PROPUESTA TÉCNICA DEL SOFTWARE | D17: 48 | E17: 02 ELABORAR PROPUESTA TÉCNICA DEL SOFTWARE DE ACUERDO CON LAS ESPECIFICACIONES TÉCNICAS DEFINIDAS. | F17: C94-R02 | G17: 2- DISEÑO | H17: 4º Trimestre | I17: 4º Trimestre | J17: =SUM(D17:D20) -> 330 | K17: =SUM(Trimestres!H27:H29) -> 144 | L17: =SUM(J17,K17)&" horas" -> 474 horas | M17: IV
B18: 220501098 | C18: ADOPCIÓN DE BUENAS PRÁCTICAS EN EL PROCESO DE DESARROLLO DE SOFTWARE | D18: 48 | E18: 01 INCORPORAR ACTIVIDADES DE ASEGURAMIENTO DE LA CALIDAD DEL SOFTWARE DE ACUERDO CON ESTÁNDARES DE LA INDUSTRIA. | F18: C98-R01 | G18: 3- IMPLEMENTACIÓN | H18: 4º Trimestre | I18: 4º Trimestre
B19: 220501096 | C19: CONSTRUCCIÓN DEL SOFTWARE | D19: 150 | E19: 02 CONSTRUIR LA BASE DE DATOS PARA EL SOFTWARE A PARTIR DEL MODELO DE DATOS. | F19: C06-R02- | G19: 3- IMPLEMENTACIÓN | H19: 4º Trimestre | I19: 4º Trimestre
B20: 220501095 | C20: MODELADO DE LOS ARTEFACTOS DEL SOFTWARE | D20: 84 | E20: 03 DETERMINAR LAS CARACTERÍSTICAS TÉCNICAS DE LA INTERFAZ GRÁFICA DEL SOFTWARE ADOPTANDO ESTÁNDARES. | F20: C95-R03 | G20: 2- DISEÑO | H20: 4º Trimestre | I20: 4º Trimestre
B21: 220501098 | C21: ADOPCIÓN DE BUENAS PRÁCTICAS EN EL PROCESO DE DESARROLLO DE SOFTWARE | D21: 48 | E21: 02 VERIFICAR LA CALIDAD DEL SOFTWARE DE ACUERDO CON LAS PRÁCTICAS ASOCIADAS EN LOS PROCESOS DE DESARROLLO. | F21: C98-R02 | G21: 3- IMPLEMENTACIÓN | H21: 5º Trimestre | I21: 5º Trimestre | J21: =SUM(D21:D25) -> 286 | K21: =SUM(Trimestres!D41:D43) -> 144 | L21: =SUM(J21,K21)&" horas" -> 430 horas | M21: VI
B22: 220501094 | C22: ELABORACIÓN DE LA PROPUESTA TÉCNICA DEL SOFTWARE | D22: 48 | E22: 03 VALIDAR LAS CONDICIONES DE LA PROPUESTA TÉCNICA DEL SOFTWARE DE ACUERDO CON LOS INTERESES DE LAS PARTES. | F22: C94-R03 | G22: 2- DISEÑO | H22: 5º Trimestre | I22: 5º Trimestre
B23: 220501095 | C23: MODELADO DE LOS ARTEFACTOS DEL SOFTWARE | D23: 84 | E23: 04 VERIFICAR LOS ENTREGABLES DE LA FASE DE DISEÑO DEL SOFTWARE DE ACUERDO CON LO ESTABLECIDO EN EL INFORME DE ANÁLISIS. | F23: C95-R04 | G23: 2- DISEÑO | H23: 5º Trimestre | I23: 5º Trimestre
B24: 220501096 | C24: CONSTRUCCIÓN DEL SOFTWARE | D24: 70 | E24: 05 REALIZAR PRUEBAS AL SOFTWARE PARA VERIFICAR SU FUNCIONALIDAD. | F24: C96-R05 | G24: 3- IMPLEMENTACIÓN | H24: 5º Trimestre | I24: 6º Trimestre
B25: 220501097 | C25: IMPLANTACIÓN DEL SOFTWARE | D25: 36 | E25: 01 PLANEAR ACTIVIDADES DE IMPLANTACIÓN DEL SOFTWARE DE ACUERDO CON LAS CONDICIONES DEL SISTEMA. | F25: C97-R01 | G25: 4- PRUEBAS / DESPLIEGUE | H25: 5º Trimestre | I25: 5º Trimestre
B26: 220501098 | C26: ADOPCIÓN DE BUENAS PRÁCTICAS EN EL PROCESO DE DESARROLLO DE SOFTWARE | D26: 48 | E26: 03 REALIZAR ACTIVIDADES DE MEJORA DE LA CALIDAD DEL SOFTWARE A PARTIR DE LOS RESULTADOS DE LA VERIFICACIÓN. | F26: C98-R03 | G26: 3- IMPLEMENTACIÓN | H26: 6º Trimestre | I26: 6º Trimestre | K26: =SUM(Trimestres!H43) -> 48
B27: 220501096 | C27: CONSTRUCCIÓN DEL SOFTWARE | D27: 70 | E27: 05 REALIZAR PRUEBAS AL SOFTWARE PARA VERIFICAR SU FUNCIONALIDAD. | F27: C96-R05 | G27: 3- IMPLEMENTACIÓN | H27: 6º Trimestre | I27: 6º Trimestre
B28: 220501097 | C28: IMPLANTACIÓN DEL SOFTWARE | D28: 36 | E28: 03 DOCUMENTAR EL PROCESO DE IMPLANTACIÓN DE SOFTWARE SIGUIENDO ESTÁNDARES DE CALIDAD. | F28: C97-R03 | G28: 4- PRUEBAS / DESPLIEGUE | H28: 6º Trimestre | I28: 6º Trimestre
B29: 220501097 | C29: IMPLANTACIÓN DEL SOFTWARE | D29: 36 | E29: 04 IMPLANTAR EL SOFTWARE DE ACUERDO CON LOS NIVELES DE SERVICIO ESTABLECIDOS CON EL CLIENTE. | F29: C97-R04 | G29: 4- PRUEBAS / DESPLIEGUE | H29: 6º Trimestre | I29: 6º Trimestre
B30: 220501096 | C30: CONSTRUCCIÓN DEL SOFTWARE | D30: 134 | E30: 04 CODIFICAR EL SOFTWARE DE ACUERDO CON EL DISEÑO ESTABLECIDO. | F30: C96-R04-Codificar | G30: 3- IMPLEMENTACIÓN | H30: 6º Trimestre | I30: 7º Trimestre
B31: 220501096 | C31: CONSTRUCCIÓN DEL SOFTWARE | D31: 31 | E31: 01 PLANEAR ACTIVIDADES DE CONSTRUCCIÓN DEL SOFTWARE DE ACUERDO CON EL DISEÑO ESTABLECIDO. | F31: C96-R01-Herramientas Dev | G31: 3- IMPLEMENTACIÓN | H31: 6º Trimestre | I31: 7º Trimestre
B32: 220501096 | C32: CONSTRUCCIÓN DEL SOFTWARE | D32: 45 | E32: 03 CREAR COMPONENTES FRONT-END DEL SOFTWARE DE ACUERDO CON EL DISEÑO. | F32: C96-R03-FronEnd | G32: 3- IMPLEMENTACIÓN | H32: 6º Trimestre | I32: 7º Trimestre
B33: 220501097 | C33: IMPLANTACIÓN DEL SOFTWARE | D33: 36 | E33: 02 DESPLEGAR EL SOFTWARE DE ACUERDO CON LA ARQUITECTURA Y LAS POLÍTICAS ESTABLECIDAS. | F33: C97-R02 | G33: 4- PRUEBAS / DESPLIEGUE | H33: 7º Trimestre | I33: 7º Trimestre
B34: 220501096 | C34: CONSTRUCCIÓN DEL SOFTWARE | D34: 134 | E34: 04 CODIFICAR EL SOFTWARE DE ACUERDO CON EL DISEÑO ESTABLECIDO. | F34: C96-R04-Codificar | G34: 3- IMPLEMENTACIÓN | H34: 7º Trimestre | I34: 7º Trimestre
B35: 220501096 | C35: CONSTRUCCIÓN DEL SOFTWARE | D35: 32 | E35: 01 PLANEAR ACTIVIDADES DE CONSTRUCCIÓN DEL SOFTWARE DE ACUERDO CON EL DISEÑO ESTABLECIDO. | F35: C96-R01-Herramientas Dev | G35: 3- IMPLEMENTACIÓN | H35: 7º Trimestre | I35: 7º Trimestre
B36: 220501096 | C36: CONSTRUCCIÓN DEL SOFTWARE | D36: 95 | E36: 03 CREAR COMPONENTES FRONT-END DEL SOFTWARE DE ACUERDO CON EL DISEÑO. | F36: C96-R03-FronEnd | G36: 3- IMPLEMENTACIÓN | H36: 7º Trimestre | I36: 7º Trimestre
